---
{"_attributes":{"version":"4.4.4+","urlbase":"https://bugs.ecmascript.org/","maintainer":"dherman@mozilla.com"},"bug":{"bug_id":1361,"creation_ts":"2013-03-20 10:43:00 -0700","short_desc":"5.2: obsolete definition of \"throw an exception\"","delta_ts":"2013-05-14 18:13:31 -0700","product":"Draft for 6th Edition","component":"editorial issue","version":"Rev 14: March 8, 2013 Draft","rep_platform":"All","op_sys":"All","bug_status":"RESOLVED","resolution":"FIXED","priority":"Normal","bug_severity":"normal","everconfirmed":true,"reporter":{"uid":"jmdyck","name":"Michael Dyck"},"assigned_to":{"uid":"allen","name":"Allen Wirfs-Brock"},"long_desc":[{"commentid":3508,"comment_count":0,"who":{"uid":"jmdyck","name":"Michael Dyck"},"bug_when":"2013-03-20 10:43:52 -0700","thetext":"In 5.2 \"Algorithm Conventions\",\nthe last paragraph says:\n    If an algorithm is defined to “throw an exception”, execution of the\n    algorithm is terminated and no result is returned. The calling algorithms\n    are also terminated, until an algorithm step is reached that explicitly\n    deals with the exception, using terminology such as “If an exception was\n    thrown…”. Once such an algorithm step has been encountered the exception\n    is no longer considered to have occurred.\n\nThis is no longer true, and has been superseded by 8.2.3.3 and 8.2.3.4.\n\nDelete the paragraph."},{"commentid":3753,"comment_count":1,"who":{"uid":"allen","name":"Allen Wirfs-Brock"},"bug_when":"2013-05-12 13:58:45 -0700","thetext":"fixed in rev15 editor's draft."},{"commentid":3917,"comment_count":2,"who":{"uid":"allen","name":"Allen Wirfs-Brock"},"bug_when":"2013-05-14 18:13:31 -0700","thetext":"resolved in rev 15, May 14, 2013 draft"}]}}
---
